C:\Users\curti\Desktop\Coding Dojo\Flask\flask_mysql>python server.py
[{u'E-mail': u'curtis@curtis.com', u'Password': u'curtis', u'ID': 1L, u'Name': u'curtis'}, {u'E-mail': u'roddy@roddy.com', u'Password': u'roddy', u'ID': 2L, u'Name': u'roddy'}, {u'E-mail': u'ruth@ruth.com', u'Password': u'ruth', u'ID': 3L, u'Name': u'ruth'}]
 * Restarting with stat
[{u'E-mail': u'curtis@curtis.com', u'Password': u'curtis', u'ID': 1L, u'Name': u'curtis'}, {u'E-mail': u'roddy@roddy.com', u'Password': u'roddy', u'ID': 2L, u'Name': u'roddy'}, {u'E-mail': u'ruth@ruth.com', u'Password': u'ruth', u'ID': 3L, u'Name': u'ruth'}]
 * Debugger is active!
 * Debugger pin code: 143-282-559
 * Running on http://127.0.0.1:5000/ (Press CTRL+C to quit)
 * Detected change in 'C:\\Users\\curti\\Desktop\\Coding Dojo\\Flask\\flask_mysql\\mysqlconnection.py', reloading
 * Restarting with stat
Traceback (most recent call last):
  File "server.py", line 8, in <module>
    print mysql.query_db("SELECT * FROM users")
  File "C:\Users\curti\Desktop\Coding Dojo\Flask\flask_mysql\mysqlconnection.py", line 21, in query_db
    result = self.db.session.execute(text(query), data)
  File "C:\Python27\lib\site-packages\sqlalchemy\orm\scoping.py", line 157, in do
    return getattr(self.registry(), name)(*args, **kwargs)
  File "C:\Python27\lib\site-packages\sqlalchemy\orm\session.py", line 1034, in execute
    bind, close_with_result=True).execute(clause, params or {})
  File "C:\Python27\lib\site-packages\sqlalchemy\orm\session.py", line 898, in _connection_for_bind
    engine, execution_options)
  File "C:\Python27\lib\site-packages\sqlalchemy\orm\session.py", line 334, in _connection_for_bind
    conn = bind.contextual_connect()
  File "C:\Python27\lib\site-packages\sqlalchemy\engine\base.py", line 2039, in contextual_connect
    self._wrap_pool_connect(self.pool.connect, None),
  File "C:\Python27\lib\site-packages\sqlalchemy\engine\base.py", line 2078, in _wrap_pool_connect
    e, dialect, self)
  File "C:\Python27\lib\site-packages\sqlalchemy\engine\base.py", line 1405, in _handle_dbapi_exception_noconnection
    exc_info
  File "C:\Python27\lib\site-packages\sqlalchemy\util\compat.py", line 202, in raise_from_cause
    reraise(type(exception), exception, tb=exc_tb, cause=cause)
  File "C:\Python27\lib\site-packages\sqlalchemy\engine\base.py", line 2074, in _wrap_pool_connect
    return fn()
  File "C:\Python27\lib\site-packages\sqlalchemy\pool.py", line 376, in connect
    return _ConnectionFairy._checkout(self)
  File "C:\Python27\lib\site-packages\sqlalchemy\pool.py", line 713, in _checkout
    fairy = _ConnectionRecord.checkout(pool)
  File "C:\Python27\lib\site-packages\sqlalchemy\pool.py", line 480, in checkout
    rec = pool._do_get()
  File "C:\Python27\lib\site-packages\sqlalchemy\pool.py", line 1060, in _do_get
    self._dec_overflow()
  File "C:\Python27\lib\site-packages\sqlalchemy\util\langhelpers.py", line 60, in __exit__
    compat.reraise(exc_type, exc_value, exc_tb)
  File "C:\Python27\lib\site-packages\sqlalchemy\pool.py", line 1057, in _do_get
    return self._create_connection()
  File "C:\Python27\lib\site-packages\sqlalchemy\pool.py", line 323, in _create_connection
    return _ConnectionRecord(self)
  File "C:\Python27\lib\site-packages\sqlalchemy\pool.py", line 449, in __init__
    self.connection = self.__connect()
  File "C:\Python27\lib\site-packages\sqlalchemy\pool.py", line 607, in __connect
    connection = self.__pool._invoke_creator(self)
  File "C:\Python27\lib\site-packages\sqlalchemy\engine\strategies.py", line 97, in connect
    return dialect.connect(*cargs, **cparams)
  File "C:\Python27\lib\site-packages\sqlalchemy\engine\default.py", line 385, in connect
    return self.dbapi.connect(*cargs, **cparams)
  File "C:\Python27\lib\site-packages\MySQLdb\__init__.py", line 81, in Connect
    return Connection(*args, **kwargs)
  File "C:\Python27\lib\site-packages\MySQLdb\connections.py", line 204, in __init__
    super(Connection, self).__init__(*args, **kwargs2)
sqlalchemy.exc.OperationalError: (_mysql_exceptions.OperationalError) (1045, "Access denied for user 'root'@'localhost' (using password: YES)")